<?xml version="1.0" ?>
<!-- =================================================================================== -->
<!-- |    This document was autogenerated by xacro from rikkert.xacro                  | -->
<!-- |    EDITING THIS FILE BY HAND IS NOT RECOMMENDED                                 | -->
<!-- =================================================================================== -->
<robot name="rikkert">
  <!-- ****************** ROBOT BASE FOOTPRINT ***************************  -->
  <!-- Define the center of the main robot chassis projected on the ground -->
  <link name="base_footprint"/>
  <!-- ********************** ROBOT BASE *********************************  -->
  <link name="base_link">
    <visual>
      <origin rpy="0 0 1.5707963267948966" xyz="0 0 -0.125"/>
      <geometry>
        <mesh filename="package://meshes/Base_platform.stl" scale="0.001 0.001 0.001"/>
      </geometry>
      <material name="Grey">
        <color rgba="0.7490196078431373 0.7490196078431373 0.7490196078431373 1.0"/>
      </material>
    </visual>
    <collision>
      <origin rpy="0 0 1.5707963267948966" xyz="0 0 -0.125"/>
      <geometry>
        <mesh filename="package://meshes/Base_platform.stl" scale="0.001 0.001 0.001"/>
      </geometry>
    </collision>
    <inertial>
      <origin rpy="1.5707963267948966 0 1.5707963267948966" xyz="0 0 0"/>
      <mass value="2"/>
      <inertia ixx="0.01" ixy="0.0" ixz="0.0" iyy="0.01" iyz="0.0" izz="0.01"/> 
    </inertial>
  </link>
  <!-- The base footprint of the robot is located underneath the chassis -->
  <joint name="footprint_base" type="fixed">
    <parent link="base_footprint"/>
    <child link="base_link"/>
    <origin rpy="0 0 0" xyz="0.0 0.0 0.125"/>
  </joint>
  <!-- *********************** DRIVE WHEELS ******************************  -->
  <link name="right_wheel">
    <visual>
      <origin rpy="0 0 -1.5707963267948966" xyz="0 0 0"/>
      <geometry>
        <mesh filename="package://meshes/Drive_Wheel.stl" scale="0.001 0.001 0.001"/>
      </geometry>
      <material name="White">
        <color rgba="1.0 1.0 1.0 1.0"/>
      </material>
    </visual>
    <collision>
      <origin rpy="0 0 -1.5707963267948966" xyz="0 0 0"/>
      <geometry>
        <mesh filename="package://meshes/Drive_Wheel.stl" scale="0.001 0.001 0.001"/>
      </geometry>
    </collision>
    <inertial>
      <origin rpy="1.5707963267948966 0 0" xyz="0 0 0"/>
      <mass value="0.1105"/>
      <inertia ixx="0.8315125000000002" ixy="0" ixz="0" iyy="0.8315125000000002" iyz="0" izz="1.5967250000000004"/>
    </inertial>
  </link>
  <!-- Connect the wheels to the base_link at the appropriate location, and 
        define a continuous joint to allow the wheels to freely rotate about
        an axis -->
  <joint name="right_wheel_joint" type="continuous">
    <parent link="base_link"/>
    <child link="right_wheel"/>
    <origin rpy="0 0 0" xyz="0.28 -0.285 0.05"/>
    <!-- <limit upper="3.1415" lower="-3.1415" effort="30" velocity="5.0"/> -->
    <axis xyz="0 1 0"/>
    <dynamics damping="0.1" friction="0.1"/>
    <limit lower="-100000000" upper="100000000" effort="1000" velocity="100000000"/>

  </joint>
  <link name="left_wheel">
    <visual>
      <origin rpy="0 0 1.5707963267948966" xyz="0 0 0"/>
      <geometry>
        <mesh filename="package://meshes/Drive_Wheel.stl" scale="0.001 0.001 0.001"/>
      </geometry>
      <material name="White">
        <color rgba="1.0 1.0 1.0 1.0"/>
      </material>
    </visual>
    <collision>
      <origin rpy="0 0 1.5707963267948966" xyz="0 0 0"/>
      <geometry>
        <mesh filename="package://meshes/Drive_Wheel.stl" scale="0.001 0.001 0.001"/>
      </geometry>
    </collision>
    <inertial>
      <origin rpy="1.5707963267948966 0 0" xyz="0 0 0"/>
      <mass value="0.1105"/>
      <inertia ixx="0.8315125000000002" ixy="0" ixz="0" iyy="0.8315125000000002" iyz="0" izz="1.5967250000000004"/>
    </inertial>
  </link>
  <!-- Connect the wheels to the base_link at the appropriate location, and 
        define a continuous joint to allow the wheels to freely rotate about
        an axis -->
  <joint name="left_wheel_joint" type="continuous">
    <parent link="base_link"/>
    <child link="left_wheel"/>
    <origin rpy="0 0 0" xyz="0.28 0.285 0.05"/>
    <!-- <limit upper="3.1415" lower="-3.1415" effort="30" velocity="5.0"/> -->
    <axis xyz="0 1 0"/>
    <limit lower="-100000000" upper="100000000" effort="1000" velocity="100000000"/>

    <dynamics damping="0.1" friction="0.1"/>
  </joint>
  <!-- *********************** CASTER WHEEL ******************************  -->
  <!-- We add a caster wheel. It will be modeled as sphere.
       We define the wheel’s geometry, material and the joint to connect it to 
       base_link at the appropriate location. -->
<link name="caster_wheel">
  <visual>
    <origin rpy="1.5708  0  0 " xyz="0 0 0"/> <!-- Oriented correctly to represent a wheel -->
    <geometry>
      <cylinder radius="0.06" length="0.04"/> <!-- Larger wheel for better ground contact -->
    </geometry>
    <material name="black">
      <color rgba="0.0 0.0 0.0 1.0"/>
    </material>
  </visual>
  <collision>
    <origin rpy="1.5708 0  0 "  xyz="0 0 0"/>
    <geometry>
      <cylinder radius="0.06" length="0.04"/> <!-- Collision geometry matches visual -->
    </geometry>
  </collision>
  <inertial>
    <origin xyz="0 0 0" rpy="0 0 0"/>
    <mass value="0.25"/> <!-- Mass slightly increased for balance -->
    <inertia ixx="0.0025" ixy="0.0" ixz="0.0" iyy="0.0025" iyz="0.0" izz="0.0025"/>
  </inertial>
</link>

<link name="caster_body">
  <visual>
    <origin rpy="0 0 0" xyz="0 0 0"/>
    <geometry>
      <cylinder radius="0.05" length="0.08"/> <!-- Caster body with larger, more balanced dimensions -->
    </geometry>
    <material name="gray">
      <color rgba="0.5 0.5 0.5 1.0"/>
    </material>
  </visual>
  <collision>
    <origin rpy="0 0 0" xyz="0 0 0"/>
    <geometry>
      <cylinder radius="0.05" length="0.08"/> <!-- Collision matches visual to prevent inconsistency -->
    </geometry>
  </collision>
  <inertial>
    <origin xyz="0 0 0" rpy="0 0 0"/>
    <mass value="0.4"/> <!-- Increased mass to provide stability -->
    <inertia ixx="0.003" ixy="0.0" ixz="0.0" iyy="0.003" iyz="0.0" izz="0.003"/>
  </inertial>
</link>


<joint name="caster_swivel_joint" type="continuous">
  <parent link="base_link"/>
  <child link="caster_body"/>
  <origin rpy="0 0 0" xyz="-0.285 0 -0.03"/> <!-- Position of caster relative to base -->
  <axis xyz="0 0 1"/> <!-- Allows swiveling around the vertical axis (z-axis) -->
  <dynamics damping="0.5" friction="0.5"/> <!-- Increased damping and friction to stabilize the caster -->
</joint>

<joint name="caster_rolling_joint" type="revolute">
  <parent link="caster_body"/>
  <child link="caster_wheel"/>
  <origin rpy="0 0 0" xyz="0 0 -0.06"/> <!-- Adjusted to match the new wheel size -->
  <axis xyz="0 1 0"/> <!-- Rolling axis is horizontal, allowing the wheel to rotate around the x-axis -->
  <dynamics damping="0.1" friction="0.1"/> <!-- Increased damping and friction to ensure smoother rolling motion -->
  <limit lower="-100000000" upper="100000000" effort="100" velocity="10"/>
</joint>


  <!-- ********************** SENSORS **************************** -->
  <link name="hokuyo">
    <visual>
      <origin rpy="0 0 0" xyz="0 0 0"/>
      <geometry>
        <mesh filename="package://meshes/Hokuyo_UTM-30LX.stl" scale="0.01 0.01 0.01"/>
      </geometry>
      <material name="black">
        <color rgba="0.0 0.0 0.0 0.9"/>
      </material>
    </visual>
    <collision>
      <origin rpy="0 0 0" xyz="0 0 0"/>
      <geometry>
        <mesh filename="package://meshes/Hokuyo_UTM-30LX.stl" scale="0.01 0.01 0.01"/>
      </geometry>
    </collision>
    <inertial>
      <origin rpy="1.5707963267948966 0 0" xyz="0 0 0"/>
      <mass value="0.3"/>
      <inertia ixx="0.8315125000000002" ixy="0" ixz="0" iyy="0.8315125000000002" iyz="0" izz="1.5967250000000004"/>
    </inertial>
  </link>

  <joint name="hokuyo_joint" type="fixed">
    <parent link="base_link"/>
    <child link="hokuyo"/>
    <origin rpy="0 0 0" xyz="0 0 0.415"/>
  </joint>
  <link name="rs_bpearl">
    <visual>
      <origin rpy="0 0 0" xyz="0 0 0"/>
      <geometry>
        <mesh filename="package://meshes/RS_BPearl.stl" scale="0.001 0.001 0.001"/>
      </geometry>
      <material name="black">
        <color rgba="0.0 0.0 0.0 0.9"/>
      </material>
    </visual>
    <collision>
      <origin rpy="0 0 0" xyz="0 0 0"/>
      <geometry>
        <mesh filename="package://meshes/RS_BPearl.stl" scale="0.001 0.001 0.001"/>
      </geometry>
    </collision>
    <inertial>
      <origin rpy="1.5707963267948966 0 0" xyz="0 0 0"/>
      <mass value="0.1105"/>
      <inertia ixx="0.8315125000000002" ixy="0" ixz="0" iyy="0.8315125000000002" iyz="0" izz="1.5967250000000004"/>
    </inertial>
  </link>
  <joint name="bpearl_joint" type="fixed">
    <parent link="base_link"/>
    <child link="rs_bpearl"/>
    <origin rpy="0 -1.5707963267948966 3.141592653589793" xyz="0.40750000000000003 0 0.30999999999999994"/>
  </joint>
</robot>
