<?xml version="1.0" ?>
<!-- =================================================================================== -->
<!-- |    This document was autogenerated by xacro from rikkert.xacro                  | -->
<!-- |    EDITING THIS FILE BY HAND IS NOT RECOMMENDED                                 | -->
<!-- =================================================================================== -->
<robot name="rikkert">
  <!-- ****************** ROBOT BASE FOOTPRINT ***************************  -->
  <!-- Define the center of the main robot chassis projected on the ground -->
  <link name="base_footprint"/>
  <!-- ********************** ROBOT BASE *********************************  -->
  <link name="base_link">
    <visual>
      <origin rpy="0 0 1.5707963267948966" xyz="0 0 -0.125"/>
      <geometry>
        <mesh filename="package://meshes/Base_platform.stl" scale="0.001 0.001 0.001"/>
      </geometry>
      <material name="Grey">
        <color rgba="0.7490196078431373 0.7490196078431373 0.7490196078431373 1.0"/>
      </material>
    </visual>
    <collision>
      <origin rpy="0 0 1.5707963267948966" xyz="0 0 -0.125"/>
      <geometry>
        <mesh filename="package://meshes/Base_platform.stl" scale="0.001 0.001 0.001"/>
      </geometry>
    </collision>
    <inertial>
      <origin rpy="1.5707963267948966 0 1.5707963267948966" xyz="0 0 0"/>
      <mass value="0.4"/>
      <inertia ixx="0.01" ixy="0.0" ixz="0.0" iyy="0.01" iyz="0.0" izz="0.01"/> 
    </inertial>
  </link>
  <!-- The base footprint of the robot is located underneath the chassis -->
  <joint name="footprint_base" type="fixed">
    <parent link="base_footprint"/>
    <child link="base_link"/>
    <origin rpy="0 0 0" xyz="0.0 0.0 0.125"/>
  </joint>
  <!-- *********************** DRIVE WHEELS ******************************  -->
  <link name="right_wheel">
    <visual>
      <origin rpy="0 0 -1.5707963267948966" xyz="0 0 0"/>
      <geometry>
        <mesh filename="package://meshes/Drive_Wheel.stl" scale="0.001 0.001 0.001"/>
      </geometry>
      <material name="White">
        <color rgba="1.0 1.0 1.0 1.0"/>
      </material>
    </visual>
    <collision>
      <origin rpy="0 0 -1.5707963267948966" xyz="0 0 0"/>
      <geometry>
        <mesh filename="package://meshes/Drive_Wheel.stl" scale="0.001 0.001 0.001"/>
      </geometry>
    </collision>
    <inertial>
      <origin rpy="1.5707963267948966 0 0" xyz="0 0 0"/>
      <mass value="0.1105"/>
      <inertia ixx="0.8315125000000002" ixy="0" ixz="0" iyy="0.8315125000000002" iyz="0" izz="1.5967250000000004"/>
    </inertial>
  </link>
  <!-- Connect the wheels to the base_link at the appropriate location, and 
        define a continuous joint to allow the wheels to freely rotate about
        an axis -->
  <joint name="right_wheel_joint" type="continuous">
    <parent link="base_link"/>
    <child link="right_wheel"/>
    <origin rpy="0 0 0" xyz="0.28 -0.285 0.05"/>
    <!-- <limit upper="3.1415" lower="-3.1415" effort="30" velocity="5.0"/> -->
    <axis xyz="0 1 0"/>
    <dynamics damping="0.01" friction="0.1"/>
    <limit lower="-100000000" upper="100000000" effort="1000" velocity="100000000"/>

  </joint>
  <link name="left_wheel">
    <visual>
      <origin rpy="0 0 1.5707963267948966" xyz="0 0 0"/>
      <geometry>
        <mesh filename="package://meshes/Drive_Wheel.stl" scale="0.001 0.001 0.001"/>
      </geometry>
      <material name="White">
        <color rgba="1.0 1.0 1.0 1.0"/>
      </material>
    </visual>
    <collision>
      <origin rpy="0 0 1.5707963267948966" xyz="0 0 0"/>
      <geometry>
        <mesh filename="package://meshes/Drive_Wheel.stl" scale="0.001 0.001 0.001"/>
      </geometry>
    </collision>
    <inertial>
      <origin rpy="1.5707963267948966 0 0" xyz="0 0 0"/>
      <mass value="0.1105"/>
      <inertia ixx="0.8315125000000002" ixy="0" ixz="0" iyy="0.8315125000000002" iyz="0" izz="1.5967250000000004"/>
    </inertial>
  </link>
  <!-- Connect the wheels to the base_link at the appropriate location, and 
        define a continuous joint to allow the wheels to freely rotate about
        an axis -->
  <joint name="left_wheel_joint" type="continuous">
    <parent link="base_link"/>
    <child link="left_wheel"/>
    <origin rpy="0 0 0" xyz="0.28 0.285 0.05"/>
    <!-- <limit upper="3.1415" lower="-3.1415" effort="30" velocity="5.0"/> -->
    <axis xyz="0 1 0"/>
    <limit lower="-100000000" upper="100000000" effort="1000" velocity="100000000"/>

    <dynamics damping="0.01" friction="0.1"/>
  </joint>
  <!-- *********************** CASTER WHEEL ******************************  -->
  <!-- We add a caster wheel. It will be modeled as sphere.
       We define the wheel’s geometry, material and the joint to connect it to 
       base_link at the appropriate location. -->
  <link name="rear_caster">
    <visual>
      <origin rpy="3.141592653589793 0 3.141592653589793" xyz="0 0 0"/>
      <geometry>
        <sphere radius="0.05"/>        </geometry>
      <material name="Blue">
        <color rgba="0.0 0.0 1.0 1.0"/>
      </material>
    </visual>
    <collision>
      <origin rpy="3.141592653589793 0 3.141592653589793" xyz="0 0 0"/>
      <geometry>
<sphere radius="0.05"/>      </geometry>
    </collision>
    <inertial>
      <mass value="0.0105"/>
      <inertia ixx="0.11617800000000003" ixy="0.0" ixz="0.0" iyy="0.11617800000000003" iyz="0.0" izz="0.11617800000000003"/>
    </inertial>
  </link>
  <joint name="caster_joint" type="continuous">
    <parent link="base_link"/>
    <child link="rear_caster"/>
    <origin rpy="0 0 0" xyz="-0.28500000000000003 0 -0.03"/>
    <limit lower="-100000000" upper="100000000" effort="1000" velocity="100000000"/>
    <axis xyz="0 1 0"/>


  </joint>
  <!-- ********************** SENSORS **************************** -->
  <link name="hokuyo">
    <visual>
      <origin rpy="0 0 0" xyz="0 0 0"/>
      <geometry>
        <mesh filename="package://meshes/Hokuyo_UTM-30LX.stl" scale="0.01 0.01 0.01"/>
      </geometry>
      <material name="black">
        <color rgba="0.0 0.0 0.0 0.9"/>
      </material>
    </visual>
    <collision>
      <origin rpy="0 0 0" xyz="0 0 0"/>
      <geometry>
        <mesh filename="package://meshes/Hokuyo_UTM-30LX.stl" scale="0.01 0.01 0.01"/>
      </geometry>
    </collision>
    <inertial>
      <origin rpy="1.5707963267948966 0 0" xyz="0 0 0"/>
      <mass value="0.3"/>
      <inertia ixx="0.8315125000000002" ixy="0" ixz="0" iyy="0.8315125000000002" iyz="0" izz="1.5967250000000004"/>
    </inertial>
  </link>
  <joint name="hokuyo_joint" type="fixed">
    <parent link="base_link"/>
    <child link="hokuyo"/>
    <origin rpy="0 0 0" xyz="0 0 0.415"/>
  </joint>
  <link name="rs_bpearl">
    <visual>
      <origin rpy="0 0 0" xyz="0 0 0"/>
      <geometry>
        <mesh filename="package://meshes/RS_BPearl.stl" scale="0.001 0.001 0.001"/>
      </geometry>
      <material name="black">
        <color rgba="0.0 0.0 0.0 0.9"/>
      </material>
    </visual>
    <collision>
      <origin rpy="0 0 0" xyz="0 0 0"/>
      <geometry>
        <mesh filename="package://meshes/RS_BPearl.stl" scale="0.001 0.001 0.001"/>
      </geometry>
    </collision>
    <inertial>
      <origin rpy="1.5707963267948966 0 0" xyz="0 0 0"/>
      <mass value="0.1105"/>
      <inertia ixx="0.8315125000000002" ixy="0" ixz="0" iyy="0.8315125000000002" iyz="0" izz="1.5967250000000004"/>
    </inertial>
  </link>
  <joint name="bpearl_joint" type="fixed">
    <parent link="base_link"/>
    <child link="rs_bpearl"/>
    <origin rpy="0 -1.5707963267948966 3.141592653589793" xyz="0.40750000000000003 0 0.30999999999999994"/>
  </joint>
</robot>
